Workbook
Name HTML_Control: $M$1:$IA$85,$IB$20:$II$45
Name HTML_Control_1: $M$1:$IA$85,$IB$20:$II$45

Sheet LINKS & LOGINS
A1: Link to Resources Login / Password Sheet Excel
A2: https://www.dropbox.com/scl/fi/a0v10irge7xq4d1boezy9/Resources.xlsx?rlkey=oe2go37ptoo553b7cvlujz5wd&st=nxnlaosl&dl=0
A4: WEBSITE | B4: USERNAME | C4: PASSWORD | D4: NOTES
A5: www.zoho.com/creator/ | B5: heilala@sagerealestate.com | C5: Sage9244SCA**** | D5: Job database (needs updating on outdoor resorts) – Slack team when using
A6: www.sagerealestate.com/webmail | B6: Your email | C6: Your password | D6: Web-Based Company Email
A7: www.dropbox.com/sh/zwu20uff9wfwzzk/AAB_BhDHHNKfIl9Wi-LWoXL6a?dl=0 | D7: Dropbox – Archived Jobs Link
A8: www.stdb.com | B8: heilala@sagerealestate.com | C8: 2021Funfun | D8: Demographic reporting (national), alert group on Skype. Select ESRI Tools – Business Analyst, open General Projects, go to “Define Areas” in the maps
A9: www.realtyrates.com | B9: heilala@sagerealestate.com | C9: sh2303 | D9: Investor and financing survey (current copy in Market Data folder on Dropbox)
A10: www.big-rigs-rv.com | B10: heilala@sagerealestate.com | C10: 9244sage | D10: Tracks RV parks that can handle big rigs
A11: www.allstays.com/pro/full/ | B11: sheilala / heilala@sagerealestate.com | C11: 9244Sage**** | D11: Campground / RV park rental listings
A12: www.airdna.co | B12: heilala@sagerealestate.com | C12: 9244Sage** | D12: Short term rental market statistics
A13: www.timeanddate.com/worldclock/distances.html | B13: No login needed | D13: Drive time to major cities
A14: www.rvia.org | B14: heilala@sagerealestate.com | D14: 9244Sage***
A15: www.fema.gov | B15: No login needed | D15: Flood maps (use search function for Map Service Center and search by address)
A16: www.fws.gov/wetlands/data/mapper.html | B16: No login needed | D16: Search by address
A17: www.upwork.com | B17: harsell@sageoutdooradvisory.com | C17: Sageoutdoor2022! | D17: Web scraper project. Contract developers to work on project.
A18: Zoning: Local municipality site or county if unincorporated (Zoning and or Planning department)
A19: Taxes: County Assessor (County GIS for parcel outlines)
A20: Travel and Tourism Statistics (in addition to local tourism organizations):
A21: www.Deanrunyan.com
A22: § www.trade.gov/travel-and-tourism-research
A23: RV Industry Statistics:
A24: https://www.rvia.org/reports-trends
A25: www.koa.com/north-american-camping-report
A26: RV Resort Searches (in addition to Allstays and Google Maps):
A27: www.Goodsam.com
A28: www.Gorving.com
A29: www.Campgrounds.rvlife.com
... A36: www.Thedyrt.com

Sheet CHAT GPT, AI HELP
B2: Hi, You'll also find copy and paste Prompts for AI, ChatGPT, or even Google Search throughout the ALL CAPS REFERENCE TABS here in Excel Templates that contain reference info to use after you perform the setup below.
B4: CHAT GPT / AI SETUP INFO: COPY AND PASTE
B6: CHAT GPT: SAVED MEMORY REPLY AND DOWNLOAD FORMATTING FOR EASY IMPLEMENTATION INTO YOUR REPORTS
B8: HUMAN USER NOTE (Not to paste into ChatGPT): User, for improved AI productivity, turn on ALL your ChatGPT memory functions in your profile Settings > Personalization, including turning on the Reference Chat History memory function, so the AI can learn and remember in all projects, folders, chats, etc. and you save time and effort with less time repeating yourself, less time teaching the AI.
B10: BELOW TO COPY AND PASTE INTO YOUR CHAT GPT ACCOUNT IN A CHAT (*NOTE: be sure you read above and turned on All memory functions)
B12: CHAT GPT / AI PROMPT: DOC / EXCEL CHAT STYLE GUIDE & WRITING STYLE (Have it in Saved Memory of your ChatGPT Account)
B13: Here are a few things to save to your "saved memory" to use across projects, folders, chats, agent mode sessions, etc., in my account.
B15: CITATION: In general, please cite your work, research, analysis, etc. with URLs, sources, and such. When calculating or extrapolating data, please show your work / calculations (whether we're in chat or agent mode, etc.), especially when you have to come up with the answers from the raw data yourself and perform the calculations for a final answer, as opposed to finding already completed data end results, when you're just sharing the information you found. Hopefully that makes sense.
B17: WHERE TO INCLUDE CITATIONS: Please always provide citations, URLs, etc. for where you found the information or data; however, please keep the citation information in the chat here for each applicable reply of yours, and don't include citations in the Word, Excel, images, tables, or other downloads. The exception is if I request the citations in a download, or if you suspect I may want citations in the download, then if you ask if I want the citation in the download before producing the download, and I confirm that I do want the citations in the download then provide them there as well.
B19: WORD DOC FORMATTING: Also, when you provide tables, Excel sheets, or table-like images for me, unless I ask for something otherwise, then please make the table header highlight color as Hex Code #E2EFDA. And if you are providing me information in a Word document, then currently please use Calibri 11 point font with 1.15 line spacing with text justified to fill left and right margins in the Word doc. Also, in these Word docs, please use bold font for headings of sections, bold font for the name of an item in a list or bullets, and the headings of any included tables. If Word tables are included in the document you provide for me to download, then those Word table headers should have the headers highlighted in the same Hex Code #E2EFDA.
B21: EXCEL & TABLE FORMATTING: When you provide an Excel spreadsheet or a table, please also use Calibri font, but this time in 10 point font with the headers highlighted in the same Hex Code #E2EFDA. For Excel, make the column widths set or adjusted so that all text or data is viewable in its cell, row, or column without me altering it afterwards. I would like the formatting in the cells to be for percentages, currency, text, or whichever is appropriate for the date to be formatted to their proper function and type. Left justify text in cells generally and center heading text in cells with the exception of the farthest left column header being left justified. Then center in the cells for numerical data generally.
B23: BULLET LISTS: Some prompts or requests will ask for bullets specifically in the reply you give. Bullets should generally be numbered bullets with the item name in each numbered bullet in bold font, then the other information or description written after the item name should be unbold in the font I've specified.
... B35: WRITING STYLE / VOICE / TONE: The writing style in chat replies, documents, and Excel worksheets / tabs is professional and neutral, suitable for use in investment-grade reports. The AI writing and replies maintain a consistent and organized output format, clearly labeling sections and subsections numerically and in bold as specified or included in this or later updated or provided style guide(s). The AI asks for clarification only when necessary, defaulting to common interpretations when unsure.

Sheet AUTHOR AI REPORT REVIEW
A1: Author's AI Report Review Help | D1: ↓ ADDITIONAL INSTRUCTIONS / STEPS / INFO BELOW ↓ | E1: YOUR PROJECT NOTES (For Sections on Left):
A2: Author's AI Report Review Prompt (Run this prompt prior to submitting the report to the reviewer)
B3: Training Video Link (Date Video Last Updated 0/0/0):
B4: *AUTHOR: USE THE CHATGPT CHAT BOX + SIGN TO SELECT "DEEP RESEARCH" MODE IN CHAT GPT, & THEN USE THE + SIGN TO UPLOAD REPORT PDF IN THE SAME MESSAGE IN THE AI CHAT BOX WITH THE PROMPT BELOW
C5: AI, Please perform a review of this PDF, which is my finished draft of the [TYPE STUDY TYPE: MARKET STUDY, REVENUE PROJECTION, FEASIBILITY STUDY] for the [TYPE PROJECT NAME] that we have been discussing in this project folder. Look for any spelling and / or grammatical errors, inconsistencies throughout, any mismatched or inconsistent same or similar information, any mathematical errors, and issues in the tables and projections where inflation or growth of expenses, revenue, ADR, or occupancy may be incorrect or a bit off. Check the headers to be sure the section name in the header matches the section title in the text portion, check the footers to be sure the pages numbers show and that the graphic bar is the appropriate width for the inside width of the margins of both portrait and landscape oriented pages. Be sure to check every single cell of every table, all narrative writing, bullets, and other charts / graphs / etc. In other words, be sure to check every single part of the document. Let me know if you find any other problematic issues. Please create a list that is easy for a human to view and check off any items you find that need to be addressed, adjusted, corrected, or edited. Identify for each item the PDF page number and also the Sage document page number and paragraph or sentence number or location on the page, table name / location / page, or another way for the User to quickly and easily locate the item to fix. Place your findings into priority groups from Highest to Lowest, and in each group be sure the items to be addressed are listed in order from occurring first in the report order to last by page number.

Sheet GENERAL TRAINING & REFERENCE

Sheet INITIAL REPORT SECTIONS

Sheet EXEC. SUMM. & SWOT

Sheet PROJ. OVERVIEW
A1: PROJECT OVERVIEW (REFERENCE & TRAINING) | D1: ↓ ADDITIONAL INSTRUCTIONS / STEPS / INFO BELOW ↓ | E1: YOUR PROJECT NOTES (For Sections on Left):
A2: Table from Excel ToT (Table of Totals) Intake Form
C3: In Excel Select in the ToT Table from Property down through Additional Development, Improvements, & Amenities, Then In Word place cursor in appropriate location for Table, then Click Word Paste Special, Click Paste Link, Select Microsoft Excel Worksheet Object, Click Ok, Adjust Table size to the page, Save.
A4: Guest Experience Write Up
C5: Utilize the Client Data form / ToT Attractions Info of who will come and why, and other discussion info with client on who they want there clients to be, or make recommendations if they were unsure.
A6: SITE IMPROVEMENTS
B7: Sites / Units Write Up
B9: Building Improvements
B11: Additional Amenities
B13: Add & Cite Images
C14: Client Provided Renderings, Site Visit Images, Site Plan, Aerial Site Google Maps, Etc.
A15: SITE ANALYSIS
B16: Update List of Site Qualities starting with Shape
C17: Add Zoning GIS Map, search for local and county GIS.
B18: Flood Map / Write Up
C19: https://msc.fema.gov/portal/home
B20: Wetlands Map / Write Up
C21: https://fwsprimary.wim.usgs.gov/wetlands/apps/wetlands-mapper/
B22: Wildfire Loss Potential Map / Write Up | D22: Wildfire Map Steps
B23: Use FEMA Wildfire EAL (Expected Annual Loss) Report Info / Map (Link Below) | D23: 1) Click the Link to Left or Paste and Bookmark https://hazards.fema.gov/nri/map 2) In the 2nd link of Dropdown Menus: Click "Expected Annual Loss", then Scroll down and Select Wildfire 3) In the Search Field: Type the City, County, or Address of the Subject - Hit Enter 4) Once the County is Highlighted with Light Blue, then zoom out enough to show all contiguous surrounding counties at minimum 5) Take a Screenshot Selection: Include only the Wildfire EAL Legend and the Counties on screen surrounding the Subject County 6) Save the Screenshot to your Project's Market Research Folder or other appropriate folder 7) Paste the Screenshot Selection of the Legend and Map into your Project Word Doc in the appropriate area
C24: https://hazards.fema.gov/nri/map
C25: NOTE: FEMA defines Wildfire Expected Annual Loss (EAL) as the average yearly loss in dollars and it is calculated by considering exposure (of life and property), annualized frequency (yearly probability of occurrence), and historic loss ratio (expected loss of assets yearly). Factors like vegetation, topography, and population density are considered. The Wildfire EAL map rating is considered "in general, year-round".
B26: Training Video Link (Date Video Last Updated 2/18/25): (Instructions =>)
C27: https://www.loom.com/share/e76c7b187a414cd3b02f070dbed6c92f?sid=50fd5cfd-9772-44ac-bdfb-c5aecbf3016c

Sheet AREA & DEMAND INDICATORS
A1: AREA ANALYSIS (REFERENCE & TRAINING) | D1: ↓ ADDITIONAL INSTRUCTIONS / STEPS / INFO BELOW ↓ | E1: YOUR PROJECT NOTES (For Sections on Left):
A2: Map Creation Training Video (Regional & Local)
B3: Training Video Link (Date Video Last Updated 0/0/0):
A5: Area & Demand Full Write-up Tool (ALL-IN-ONE) for the below AI Prompts for sections possible:
B6: GPT Link for ChatGPT - for All available Area & Demand Write Ups
C7: https://chatgpt.com/g/g-67fb14f8f1908191ad2df2bda899f0d5-area-and-demand-write-up-tool
B8: *OR Separate Prompts for each separate write-up section possible for Area & Demand are below
A10: Write Ups Chat GPT How-To (State, County, Local)
B11: State
B12: Example Chat GPT Summary Prompt Text (Copy & Paste):
C13: Write up a 3 paragraph overview of the state of [TYPE STATE] including geography, economy, population and transportation data.
B14: County
B15: Example Chat GPT Summary Prompt Text (Copy & Paste):
C16: Write up a 3 paragraph overview of the county of [TYPE COUNTY, STATE] including geography, economy, population and transportation data.
B17: Local
B18: Example Chat GPT Summary Prompt Text (Copy & Paste):
C19: Write up a 3 paragraph overview of [TYPE CITY, STATE] including geography, economy, population and transportation data.
A21: DEMAND INDICATORS
A22: Weather | B22: https://weatherspark.com/
B23: Training Video Link (Date Video Last Updated 0/0/0):
A26: Tourism Trends
B27: State
B28: Example Chat GPT Summary Prompt Text (Copy & Paste):
C29: Write up 3 paragraphs on state of [TYPE STATE] tourism development and statistics. Please cite your findings and include any graphic charts, tables, or graphs that also represent the statistics you find.
B30: Local / Area Attractions & Events
B31: Example Chat GPT Summary Prompt Text (Copy & Paste):
C32: WRITE UP: Write up 3 paragraphs on both the city and county of [TYPE CITY, COUNTY in STATE] tourism development and statistics. Please cite your findings and include any graphic charts, tables, or graphs that also represent the statistics you find.
C33: LIST OF ATTRACTIONS & EVENTS: Create separate lists for both the city and county of [TYPE CITY, COUNTY, OR OTHER GEOGRAPHIC AREA, IN STATE] with the lists further separating for each geographic area, the area attractions from the area events which are in or near the city or county. Make these lists exhaustive with any and all possibilities that exist. Please cite your findings.
A35: What's In My Community (STDB) (*Instructions to Right =>) | D35: STDB HOW-TO (Multiple Parts as outlined on left)
B36: Training Video Link (Date Video Last Updated 0/0/0): | D36: STDB = Site to do Business (uses credits for each report / request) STEP 1: Be sure no one else is on STDB... if No one is on, then Post to the whole Team 1st that you're "On STDB" LOGIN as Subscriber to STDB - * Select / Click Business Analyst Button NEXT INITIAL STDB MULTI-PART PROJECT STEPS: Click Maps, Click Define Areas, In the Left Dropdown's Search Bar, Enter Location / Address, or Click the Pin Button by search bar then Select a Location on the Map What's In My Community Infographic Steps 1) Select Drive Time, Type 15, Select Minutes, Click Apply, Click Finish 2) Click Run Infographics, Click Box in menu for What's In My Community? 3) In Right Side Box that populated: Click Run Now - for your preferred location 4) Once Infographic Populates: Export it as an Image (or take screenshot selection of it), Save in your Market Research Folder for the Project 5) Copy and Paste Infographic Image into the appropriate section of your report doc Traffic Count Map Steps 1) Click Maps, On Left Pop-Up Menu Click Back Button/Arrow, Click Rings 2) Type 1, 3, 5, Select Miles, Click Apply, Click Finish 3) In the Pop Up Menu on the Right, Click Run Reports 4) Scroll to and Click Box in the next menu for Traffic Count Map 5) In Right Side Box that populated: Click Run Now - for your preferred location 6) Once processed: Click Download in left side box, then Save the Downloaded Traffic Count Map PDF in your Market Research Folder for the Project 7) Open PDF, Export as an Image, Copy and Paste Image into the appropriate section of your report doc
B37: https://www.stdb.com/
B38: National Parks - NOTE: if park is > 2 hour drive from subject, then could omit that park(s)
B39: Example Chat GPT Summary Prompt Text (Copy & Paste):
C40: Create an exhaustive list of all national parks, monuments, or memorials that are within the state of [TYPE STATE] with some information about them and include both their distance in miles and drive time from [TYPE SUBJECT'S TOWN, GPS COORDINATES, OR ADDRESS]. Prioritize finding ones that are within approximately a 2 hour drive time from the most finite location provided. List them from closest to farthest. Also, if you can access the latest year's number of annual visitors, please provide that too and cite where that information was found for all parks or each park.
B41: State Parks - NOTE: if park is > 90 minutes drive from subject, then could omit that park(s)
B42: Example Chat GPT Summary Prompt Text (Copy & Paste):
C43: Create an exhaustive list of all state parks, state recreation areas, state memorials, or state monuments that are within the state of [TYPE STATE] and are also within approximately 90 minutes or less drive time from [TYPE SUBJECT'S TOWN, GPS COORDINATES, OR ADDRESS]. List them from closest to farthest. Include a short summary about each of them. Include the number of annual visitors for each during [TYPE YEAR], and include both the distance in miles and drive time from [TYPE SUBJECT'S TOWN, GPS COORDINATES, OR ADDRESS] to each park. Please cite where the annual visitor numbers or statistics were found.
B44: Other Special Major Attractions?
A46: Transportation
B48: Highway and Road Access - Traffic Count Map (STDB) (*Instructions to Right =>)
...

Sheet Market Profile
AH2: Annual Growth | AI2: Years | AJ2: 5 | AL2: User Can Change
AH3: Projected Growth Years (Population and Household) | AJ3: 5 | AL3: User Can Change
D4: MARKET PROFILE | AH4: Projected Growth Years (Income) | AJ4: 5
A5: Miles or Minutes will pull from the excel | F5: ='60 Min 120 Min 180 Min'!B10 -> 60 minutes | I5: ='60 Min 120 Min 180 Min'!C10 -> 120 minutes | L5: ='60 Min 120 Min 180 Min'!D10 -> 180 minutes | O5: City | R5: County | U5: MSA | X5: USA
D7: Population | AH7: Get Market Profile in Excel (Miles or Drive Time, City, County, MSA) USA Info is Current
D8: 2020 Population | F8: ='60 Min 120 Min 180 Min'!B12 -> 1708977 | I8: ='60 Min 120 Min 180 Min'!C12 -> 5890181 | L8: ='60 Min 120 Min 180 Min'!D12 -> 6396575 | O8: =City!B10 -> 26785 | R8: =County!B10 -> 425264 | U8: =MSA!B10 -> 4845832 | X8: =USA!B10 -> 331449281 | AH8: Go to Cell A1 in the STDB Spreadsheet Download
D9: 2025 Population | F9: ='60 Min 120 Min 180 Min'!B14 -> 1844100 | I9: ='60 Min 120 Min 180 Min'!C14 -> 6290418 | L9: ='60 Min 120 Min 180 Min'!D14 -> 6818085 | O9: =City!B12 -> 28129 | R9: =County!B12 -> 492312 | U9: =MSA!B12 -> 5215050 | X9: =USA!B12 -> 339887819 | AH9: Ctrl A (select all) then Ctrl C (copy)
D10: 2030 Projected Population | F10: ='60 Min 120 Min 180 Min'!B16 -> 1948548 | I10: ='60 Min 120 Min 180 Min'!C16 -> 6584040 | L10: ='60 Min 120 Min 180 Min'!D16 -> 7130239 | O10: =City!B14 -> 30132 | R10: =County!B14 -> 555032 | U10: =MSA!B14 -> 5491123 | X10: =USA!B14 -> 347149422 | AH10: Then go to the appropriate spreadsheet (60 min, 120 min, 180 min, City, County, MSA)
D11: Annual Growth Rate 2010 to 2025 | F11: =(1-(F8/F9))/AJ2 -> 0.014654628 | I11: =(1-(I8/I9))/AJ2 -> 0.012725291 | L11: =(1-(L8/L9))/AJ2 -> 0.012364469 | O11: =(1-(O8/O9))/AJ2 -> 0.0095559743 | R11: =(1-(R8/R9))/AJ2 -> 0.027238012 | U11: =(1-(U8/U9))/AJ2 -> 0.014159711 | X11: =(1-(X8/X9))/AJ2 -> 0.0049654842 | AH11: Go to Cell A1 and hit Paste (Ctrl V)
D12: Projected Annual Growth Rate 2025 to 2030 | F12: =(1-(F9/F10))/AJ3 -> 0.010720598 | I12: =(1-(I9/I10))/AJ3 -> 0.0089192046 | L12: =(1-(L9/L10))/AJ3 -> 0.0087557794 | O12: =(1-(O9/O10))/AJ3 -> 0.013294836 | R12: =(1-(R9/R10))/AJ3 -> 0.022600499 | U12: =(1-(U9/U10))/AJ3 -> 0.010055247 | X12: =(1-(X9/X10))/AJ3 -> 0.0041835605
D13: Households
D14: 2020 Households | F14: ='60 Min 120 Min 180 Min'!B25 -> 625018 | I14: ='60 Min 120 Min 180 Min'!D23 -> 2121584 | L14: ='60 Min 120 Min 180 Min'!D25 -> 2429092 | O14: =City!B23 -> 4866 | R14: =County!B23 -> 146663 | U14: =MSA!B23 -> 1790242 | X14: =USA!B23 -> 126817580
D15: 2025 Households | F15: ='60 Min 120 Min 180 Min'!B27 -> 687370 | I15: ='60 Min 120 Min 180 Min'!D27 -> 2634592 | L15: ='60 Min 120 Min 180 Min'!D27 -> 2634592 | O15: =City!B25 -> 6164 | R15: =County!B25 -> 175296 | U15: =MSA!B25 -> 1959001 | X15: =USA!B25 -> 132422916
D16: 2025 Average Household Size | F16: ='60 Min 120 Min 180 Min'!B28 -> 2.64 | I16: ='60 Min 120 Min 180 Min'!D28 -> 2.54 | L16: ='60 Min 120 Min 180 Min'!D26 -> 2.58 | O16: =City!B26 -> 2.31 | R16: =MSA!C25 -> 0 | U16: =MSA!B26 -> 2.61 | X16: =USA!B26 -> 2.5
D17: 2030 Projected Households | F17: ='60 Min 120 Min 180 Min'!B29 -> 733275 | I17: ='60 Min 120 Min 180 Min'!D29 -> 2785885 | L17: ='60 Min 120 Min 180 Min'!D29 -> 2785885 | O17: =City!B27 -> 7097 | R17: =County!B27 -> 201050 | U17: =MSA!B27 -> 2085679 | X17: =USA!B27 -> 136716884
D18: 2030 Average Household Size | F18: ='60 Min 120 Min 180 Min'!B30 -> 2.61 | I18: ='60 Min 120 Min 180 Min'!D30 -> 2.51 | L18: ='60 Min 120 Min 180 Min'!D30 -> 2.51 | O18: =City!B28 -> 2.29 | R18: =County!B28 -> 2.66 | U18: =MSA!B28 -> 2.59 | X18: =USA!B28 -> 2.48
D19: Annual Growth Rate 2010 to 2025 | F19: =(1-(F14/F15))/AJ2 -> 0.018142194 | I19: =(1-(I14/I15))/AJ2 -> 0.038944019 | L19: =(1-(L14/L15))/AJ2 -> 0.015600138 | O19: =(1-(O14/O15))/AJ2 -> 0.042115509 | R19: =(1-(R14/R15))/AJ2 -> 0.032668173 | U19: =(1-(U14/U15))/AJ2 -> 0.017229088 | X19: =(1-(X14/X15))/AJ2 -> 0.0084658096
D20: Projected Annual Growth Rate 2025 to 2030 | F20: =(1-(F15/F17))/AJ3 -> 0.012520541 | I20: =(1-(I15/I17))/AJ3 -> 0.010861396 | L20: =(1-(L15/L17))/AJ3 -> 0.010861396 | O20: =(1-(O15/O17))/AJ3 -> 0.0262928 | R20: =(1-(R15/R17))/AJ3 -> 0.025619498 | U20: =(1-(U15/U17))/AJ3 -> 0.012147411 | X20: =(1-(X15/X17))/AJ3 -> 0.0062815475
D21: Income
D22: 2025 Median Household Income | F22: ='60 Min 120 Min 180 Min'!B39 -> 97574 | I22: ='60 Min 120 Min 180 Min'!C39 -> 88369 | L22: ='60 Min 120 Min 180 Min'!D39 -> 85928 | O22: =City!B37 -> 76645 | R22: =County!B37 -> 79828 | U22: =MSA!B37 -> 92045 | X22: =USA!B37 -> 81624
D23: 2030 Projected Median Household Income | F23: ='60 Min 120 Min 180 Min'!B40 -> 109859 | I23: ='60 Min 120 Min 180 Min'!C40 -> 102985 | L23: ='60 Min 120 Min 180 Min'!D40 -> 100739 | O23: =City!B38 -> 82271 | R23: =County!B38 -> 88591 | U23: =MSA!B38 -> 105919 | X23: =USA!B38 -> 92476
D24: Projected Annual Growth Rate 2025 to 2030 | F24: =(1-(F22/F23))/AJ4 -> 0.022365032 | I24: =(1-(I22/I23))/AJ4 -> 0.028384716 | L24: =(1-(L22/L23))/AJ4 -> 0.029404699 | O24: =(1-(O22/O23))/AJ4 -> 0.013676751 | R24: =(1-(R22/R23))/AJ4 -> 0.019783048 | U24: =(1-(U22/U23))/AJ4 -> 0.026197377 | X24: =(1-(X22/X23))/AJ4 -> 0.023469873
A25: You Can Hide | D25: 2025 Percentage of Households Earning Over $200,000 | F25: ='60 Min 120 Min 180 Min'!B63+'60 Min 120 Min 180 Min'!B64+'60 Min 120 Min 180 Min'!B65+'60 Min 120 Min 180 Min'!B66+'60 Min 120 Min 180 Min'!B67 -> 0.1609 | I25: ='60 Min 120 Min 180 Min'!C63+'60 Min 120 Min 180 Min'!C64+'60 Min 120 Min 180 Min'!C65+'60 Min 120 Min 180 Min'!C66+'60 Min 120 Min 180 Min'!C67 -> 0.1456 | L25: ='60 Min 120 Min 180 Min'!D63+'60 Min 120 Min 180 Min'!D64+'60 Min 120 Min 180 Min'!D65+'60 Min 120 Min 180 Min'!D66+'60 Min 120 Min 180 Min'!D67 -> 0.1398 | O25: =City!B61+City!B62+City!B63+City!B64+City!B65 -> 0.0911 | R25: =County!B61+County!B62+County!B63+County!B64+County!B65 -> 0.0747 | U25: =MSA!B61+MSA!B62+MSA!B63+MSA!B64+MSA!B65 -> 0.155 | X25: =USA!B61+USA!B62+USA!B63+USA!B64+USA!B65 -> 0.1396
D26: Home Values
D27: 2025 Median Home Value | F27: ='60 Min 120 Min 180 Min'!B76 -> 463802 | I27: ='60 Min 120 Min 180 Min'!C76 -> 448870 | L27: ='60 Min 120 Min 180 Min'!D76 -> 442098 | O27: =City!B74 -> 370831 | R27: =County!B74 -> 380767 | U27: =MSA!B74 -> 472406 | X27: =USA!B74 -> 370578
D28: 2025 Average Home Value | F28: ='60 Min 120 Min 180 Min'!B94 -> 513053 | I28: ='60 Min 120 Min 180 Min'!C94 -> 521774 | L28: ='60 Min 120 Min 180 Min'!D94 -> 512217 | O28: =City!B92 -> 373729 | R28: =County!B92 -> 403103 | U28: =MSA!B92 -> 552860 | X28: =USA!B92 -> 476461
D29: Housing Unit Summary
D30: Owner Occupied Housing Units | F30: ='60 Min 120 Min 180 Min'!B106 -> 0.7284 | I30: ='60 Min 120 Min 180 Min'!C106 -> 0.6746 | L30: ='60 Min 120 Min 180 Min'!D106 -> 0.6821 | O30: =City!B104 -> 0.8616 | R30: =County!B104 -> 0.8342 | U30: =MSA!B104 -> 0.6746 | X30: =USA!B104 -> 0.6423
D31: Renter Occupied Housing Units | F31: ='60 Min 120 Min 180 Min'!B107 -> 0.2716 | I31: ='60 Min 120 Min 180 Min'!C107 -> 0.3254 | L31: ='60 Min 120 Min 180 Min'!D107 -> 0.3179 | O31: =City!B105 -> 0.1384 | R31: =County!B105 -> 0.1658 | U31: =MSA!B105 -> 0.3254 | X31: =USA!B105 -> 0.3577
D32: Vacant Housing Units | F32: ='60 Min 120 Min 180 Min'!B108 -> 0.0984 | I32: ='60 Min 120 Min 180 Min'!C108 -> 0.0916 | L32: ='60 Min 120 Min 180 Min'!D108 -> 0.1014 | O32: =City!B106 -> 0.2205 | R32: =County!B106 -> 0.1411 | U32: =MSA!B106 -> 0.0937 | X32: =USA!B106 -> 0.0979
D33: 2023 Unemployment Rate | F33: =#REF!/100 -> #REF! | I33: =#REF!/100 -> #REF! | L33: =#REF!/100 -> #REF! | O33: =#REF!/100 -> #REF! | R33: =#REF!/100 -> #REF! | U33: =#REF!/100 -> #REF! | X33: =#REF!/100 -> #REF! | AH33: You Can Hide
D34: 2025 Consumer Spending
D35: 2025 Average Household Entertainment / Recreation Spending | F35: ='60 Min 120 Min 180 Min'!B239 -> 4500.88 | I35: ='60 Min 120 Min 180 Min'!C239 -> 4263.24 | L35: ='60 Min 120 Min 180 Min'!D239 -> 4182.35 | O35: =City!B237 -> 3580.16 | R35: =County!B237 -> 3537.64 | U35: =MSA!B237 -> 4403.74 | X35: =USA!B237 -> 4108.79
D36: Spending Potential Index | F36: ='60 Min 120 Min 180 Min'!B240 -> 110 | I36: ='60 Min 120 Min 180 Min'!C240 -> 104 | L36: ='60 Min 120 Min 180 Min'!D240 -> 102 | O36: =City!B238 -> 87 | R36: =County!B244 -> 85 | U36: =MSA!B247 -> 107 | X36: =USA!B238 -> 100
D37: 2025 Average Household Travel Spending | F37: ='60 Min 120 Min 180 Min'!B265 -> 3987.52 | I37: ='60 Min 120 Min 180 Min'!C265 -> 3746.05 | L37: ='60 Min 120 Min 180 Min'!D265 -> 3666.63 | O37: =City!B263 -> 3224.6 | R37: =County!B263 -> 3061 | U37: =MSA!B263 -> 3890.29 | X37: =USA!B263 -> 3608.4
D38: Spending Potential Index | F38: ='60 Min 120 Min 180 Min'!B266 -> 111 | I38: ='60 Min 120 Min 180 Min'!C266 -> 104 | L38: ='60 Min 120 Min 180 Min'!D266 -> 102 | O38: =City!B264 -> 89 | R38: =County!B264 -> 85 | U38: =MSA!B264 -> 108 | X38: =USA!B267 -> 100
D40: Source: Market Profile Derived From ESRI
D41: Data Note: The Spending Potential Index represents the amount spent in the area relative to a national average of 100.

Sheet 60 Min 120 Min 180 Min
A2: Market Profile
A3: Prepared by Esri
A4: 1140 W Butte Ave, Florence, Arizona, 85132 (60 minutes, 120 minutes, 180 minutes)
A5: 1140 W Butte Ave, Florence, Arizona, 85132 (60 minutes), 1140 W Butte Ave, Florence, Arizona, 85132 (120 minutes), 1140 W Butte Ave, Florence, Arizona, 85132 (180 minutes)
A6: Drive time: 60, 120, 180 minute radii
A7: Latitude: 33.03182
A8: Longitude: -111.40332
A10: Population Summary | B10: 60 minutes | C10: 120 minutes | D10: 180 minutes
A11: 2010 Total Population | B11: 1459417 | C11: 5174419 | D11: 5659182
A12: 2020 Total Population | B12: 1708977 | C12: 5890181 | D12: 6396575
A13: 2020 Group Quarters | B13: 33259 | C13: 120391 | D13: 130025
A14: 2025 Total Population | B14: 1844100 | C14: 6290418 | D14: 6818085
A15: 2025 Group Quarters | B15: 32239 | C15: 125337 | D15: 133772
A16: 2030 Total Population | B16: 1948548 | C16: 6584040 | D16: 7130239
A17: 2025-2030 Annual Rate | B17: 0.0111 | C17: 0.0092 | D17: 0.009
A18: 2025 Total Daytime Population | B18: 1701951 | C18: 6233107 | D18: 6749181
A19: Workers | B19: 763295 | C19: 3018959 | D19: 3213087
A20: Residents | B20: 938656 | C20: 3214148 | D20: 3536094
A22: Household Summary
A23: 2010 Total Households | B23: 532077 | C23: 1926443 | D23: 2121584
A24: 2010 Average Household Size | B24: 2.68 | C24: 2.63 | D24: 2.61
A25: 2020 Total Households | B25: 625018 | C25: 2217267 | D25: 2429092
A26: 2020 Average Household Size | B26: 2.68 | C26: 2.6 | D26: 2.58
A27: 2025 Total Households | B27: 687370 | C27: 2410317 | D27: 2634592
A28: 2025 Average Household Size | B28: 2.64 | C28: 2.56 | D28: 2.54
A29: 2030 Total Households | B29: 733275 | C29: 2551646 | D29: 2785885
A30: 2030 Average Household Size | B30: 2.61 | C30: 2.53 | D30: 2.51
A31: 2025-2030 Annual Rate | B31: 0.013 | C31: 0.0115 | D31: 0.0112
A32: 2025 Families | B32: 471113 | C32: 1548506 | D32: 1689128
A33: 2025 Average Family Size | B33: 3.15 | C33: 3.15 | D33: 3.13
A34: 2030 Families | B34: 502258 | C34: 1631981 | D34: 1778102
... A36: 2025-2030 Growth Rate | B36: 0.0129 | C36: 0.0106 | D36: 0.0103
A38: Median Household Income
A39: 2025 | B39: 97574 | C39: 88369 | D39: 85928
A40: 2030 | B40: 109859 | C40: 102985 | D40: 100739
A42: Per Capita Income | B42: 60 minutes | C42: 120 minutes | D42: 180 minutes
A43: 2025 | B43: 47788 | C43: 46730 | D43: 46065
A44: 2030 | B44: 53733 | C44: 53093 | D44: 52335
A46: 2025 Households by Income
A47: Household Income Base | B47: 687343 | C47: 2410216 | D47: 2634477
...

Sheet City
A2: Market Profile
A3: Prepared by Esri
A4: Florence Town, AZ (Florence town...)
A5: Florence Town, AZ (0423760)
A6: Geography: Place
A8: Population Summary | B8: Florence town...
A9: 2010 Total Population | B9: 25539
A10: 2020 Total Population | B10: 26785
A11: 2020 Group Quarters | B11: 15355
A12: 2025 Total Population | B12: 28129
A13: 2025 Group Quarters | B13: 13913
A14: 2030 Total Population | B14: 30132
A15: 2025-2030 Annual Rate | B15: 0.0139
A16: 2025 Total Daytime Population | B16: 20632
A17: Workers | B17: 10612
A18: Residents | B18: 10020
A20: Household Summary
A21: 2010 Total Households | B21: 3330
A22: 2010 Average Household Size | B22: 2.35
A23: 2020 Total Households | B23: 4866
A24: 2020 Average Household Size | B24: 2.35
A25: 2025 Total Households | B25: 6164
A26: 2025 Average Household Size | B26: 2.31
A27: 2030 Total Households | B27: 7097
A28: 2030 Average Household Size | B28: 2.29
A29: 2025-2030 Annual Rate | B29: 0.0286
A30: 2025 Families | B30: 4263
A31: 2025 Average Family Size | B31: 2.73
A32: 2030 Families | B32: 4972
... A34: 2025-2030 Growth Rate | B34: 0.0312
A36: Median Household Income
A37: 2025 | B37: 76645
A38: 2030 | B38: 82271
A40: Per Capita Income | B40: Florence town...
A41: 2025 | B41: 24811
A42: 2030 | B42: 28891
A44: 2025 Households by Income
A45: Household Income Base | B45: 6157
A46: <$10,000 | B46: 0.0799
A47: $10,000-14,999 | B47: 0.0151
...

Sheet County
A2: Market Profile
A3: Prepared by Esri
A4: Pinal County, AZ (Pinal County,...)
A5: Pinal County, AZ (04021)
A6: Geography: County
A8: Population Summary | B8: Pinal County,...
A9: 2010 Total Population | B9: 375770
A10: 2020 Total Population | B10: 425264
A11: 2020 Group Quarters | B11: 22770
A12: 2025 Total Population | B12: 492312
A13: 2025 Group Quarters | B13: 20632
A14: 2030 Total Population | B14: 555032
A15: 2025-2030 Annual Rate | B15: 0.0243
A16: 2025 Total Daytime Population | B16: 413892
A17: Workers | B17: 122891
A18: Residents | B18: 291001
A20: Household Summary
A21: 2010 Total Households | B21: 125590
A22: 2010 Average Household Size | B22: 2.78
A23: 2020 Total Households | B23: 146663
A24: 2020 Average Household Size | B24: 2.74
A25: 2025 Total Households | B25: 175296
A26: 2025 Average Household Size | B26: 2.69
A27: 2030 Total Households | B27: 201050
A28: 2030 Average Household Size | B28: 2.66
A29: 2025-2030 Annual Rate | B29: 0.0278
A30: 2025 Families | B30: 126003
A31: 2025 Average Family Size | B31: 3.14
A32: 2030 Families | B32: 143951
... A34: 2025-2030 Growth Rate | B34: 0.027
A36: Median Household Income
A37: 2025 | B37: 79828
A38: 2030 | B38: 88591
A40: Per Capita Income | B40: Pinal County,...
A41: 2025 | B41: 35490
A42: 2030 | B42: 40098
A44: 2025 Households by Income
A45: Household Income Base | B45: 175286
A46: <$10,000 | B46: 0.0588
A47: $10,000-14,999 | B47: 0.0252
...

Sheet MSA
A2: Market Profile
A3: Prepared by Esri
A4: Phoenix-Mesa-Chandler, AZ Metropolitan Statistical Area (Phoenix-Mesa-...)
A5: Phoenix-Mesa-Chandler, AZ Metropolitan Statistical Area (38060)
A6: Geography: CBSA
A8: Population Summary | B8: Phoenix-Mesa-...
A9: 2010 Total Population | B9: 4192887
A10: 2020 Total Population | B10: 4845832
A11: 2020 Group Quarters | B11: 92800
A12: 2025 Total Population | B12: 5215050
A13: 2025 Group Quarters | B13: 98282
A14: 2030 Total Population | B14: 5491123
A15: 2025-2030 Annual Rate | B15: 0.0104
A16: 2025 Total Daytime Population | B16: 5165796
A17: Workers | B17: 2533342
A18: Residents | B18: 2632454
A20: Household Summary
A21: 2010 Total Households | B21: 1537173
A22: 2010 Average Household Size | B22: 2.68
A23: 2020 Total Households | B23: 1790242
A24: 2020 Average Household Size | B24: 2.65
A25: 2025 Total Households | B25: 1959001
A26: 2025 Average Household Size | B26: 2.61
A27: 2030 Total Households | B27: 2085679
A28: 2030 Average Household Size | B28: 2.59
A29: 2025-2030 Annual Rate | B29: 0.0126
A30: 2025 Families | B30: 1280511
A31: 2025 Average Family Size | B31: 3.19
A32: 2030 Families | B32: 1357196
... A34: 2025-2030 Growth Rate | B34: 0.0117
A36: Median Household Income
A37: 2025 | B37: 92045
A38: 2030 | B38: 105919
A40: Per Capita Income | B40: Phoenix-Mesa-...
A41: 2025 | B41: 47465
A42: 2030 | B42: 53778
A44: 2025 Households by Income
A45: Household Income Base | B45: 1958915
A46: <$10,000 | B46: 0.0463
A47: $10,000-14,999 | B47: 0.0215
...

Sheet USA
A2: Market Profile
A3: Prepared by Esri
A4: United States 12 (United States)
A5: United States (01)
A6: Geography: USA
A8: Population Summary | B8: United States
A9: 2010 Total Population | B9: 308745538
A10: 2020 Total Population | B10: 331449281
A11: 2020 Group Quarters | B11: 8239016
A12: 2025 Total Population | B12: 339887819
A13: 2025 Group Quarters | B13: 8216660
A14: 2030 Total Population | B14: 347149422
A15: 2025-2030 Annual Rate | B15: 0.0042
A16: 2025 Total Daytime Population | B16: 338218372
A17: Workers | B17: 165993009
A18: Residents | B18: 172225363
A20: Household Summary
A21: 2010 Total Households | B21: 116716292
A22: 2010 Average Household Size | B22: 2.58
A23: 2020 Total Households | B23: 126817580
A24: 2020 Average Household Size | B24: 2.55
A25: 2025 Total Households | B25: 132422916
A26: 2025 Average Household Size | B26: 2.5
A27: 2030 Total Households | B27: 136716884
A28: 2030 Average Household Size | B28: 2.48
A29: 2025-2030 Annual Rate | B29: 0.0064
A30: 2025 Families | B30: 84464295
A31: 2025 Average Family Size | B31: 3.13
A32: 2030 Families | B32: 86759582
... A34: 2025-2030 Growth Rate | B34: 0.0054
A36: Median Household Income
A37: 2025 | B37: 81624
A38: 2030 | B38: 92476
A40: Per Capita Income | B40: United States
A41: 2025 | B41: 45360
A42: 2030 | B42: 50744
A44: 2025 Households by Income
A45: Household Income Base | B45: 132419468
A46: <$10,000 | B46: 0.0502
A47: $10,000-14,999 | B47: 0.0327
...

Sheet State Parks
B3: # | C3: Name | D3: Address | E3: Miles from Subject | F3: 2022-2023 Annual Visitors
B4: 1 | C4: South Cumberland State Park, TN | E4: 28 Miles | F4: 571681
B5: 2 | C5: Cloudland Canyon State Park, GA | E5: 26 Miles | F5: 302309
E7: Total | F7: =SUM(F4:F6) -> 873990
D15: =SUM(I22,J22,K22,S22,T22) -> 0 | H15: Parks | I15: JAN | J15: FEB | K15: MAR | L15: APR | M15: MAY | N15: JUN | O15: JUL | P15: AUG | Q15: SEP | R15: OCT | S15: NOV | T15: DEC | U15: Total
D16: =SUM(L22,M22,Q22,R22) -> 0 | U16: 204424
D17: =SUM(N22:P22) -> 0 | U17: 103213
D18: =SUM(M22:R22) -> 0 | U18: 201331
U19: 131263
U20: 2467245
H21: Sum | I21: =SUM(I16:I20) -> 0 | J21: =SUM(J16:J20) -> 0 | K21: =SUM(K16:K20) -> 0 | L21: =SUM(L16:L20) -> 0 | M21: =SUM(M16:M20) -> 0 | N21: =SUM(N16:N20) -> 0 | O21: =SUM(O16:O20) -> 0 | P21: =SUM(P16:P20) -> 0 | ... U21: =SUM(U16:U20) -> 3107476
H22: % of Total | I22: =I21/$U$21 -> 0 | J22: =J21/$U$21 -> 0 | K22: =K21/$U$21 -> 0 | L22: =L21/$U$21 -> 0 | M22: =M21/$U$21 -> 0 | N22: =N21/$U$21 -> 0 | O22: =O21/$U$21 -> 0 | P22: =P21/$U$21 -> 0 | ... T22: =T21/$U$21 -> 0 | U22: 1
H23: % of July | I23: =I21/$O$21 -> #DIV/0! | J23: =J21/$O$21 -> #DIV/0! | K23: =K21/$O$21 -> #DIV/0! | L23: =L21/$O$21 -> #DIV/0! | M23: =M21/$O$21 -> #DIV/0! | N23: =N21/$O$21 -> #DIV/0! | O23: =O21/$O$21 -> #DIV/0! | P23: =P21/$O$21 -> #DIV/0! | ... T23: =T21/$O$21 -> #DIV/0! | U23: 1

Sheet Nat. Parks
C1: Visitation by park=> | D1: https://irma.nps.gov/STATS/SSRSReports/Park%20Specific%20Reports/Visitation%20by%20Month?Park=MNRR
C2: Map of parks => | D2: https://irma.nps.gov/STATS/
B4: # | C4: Name | D4: Time to Subject | E4: 2022 Annual Visitors
B5: 1 | C5: =G11 -> Indianna Dunes NP | D5: 2 hrs | E5: =T13 -> 2834180
B6: 2 | C6: =G29 -> George Rogers Clark NHP | D6: 2 hrs 45 min | E6: =T31 -> 123229
B7: 3 | C7: =G47 -> Lincoln Boyhood NMEM | D7: 3 hrs | E7: =T49 -> 105819
D9: Total | E9: =SUM(E5:E8) -> 3063228
G11: Indianna Dunes NP
C12: Seasonal Demand | H12: JAN | I12: FEB | J12: MAR | K12: APR | L12: MAY | M12: JUN | N12: JUL | O12: AUG | P12: SEP | Q12: OCT | R12: NOV | S12: DEC | T12: Annual Total | U12: YoY % Change
C13: Low Season (Nov-March) | D13: =SUM(H25,I25,J25,R25,S25) -> 0.19263811 | G13: 2022 | H13: 71633 | I13: 74372 | J13: 127431 | K13: 141437 | L13: 234403 | M13: 438727 | N13: 575495 | O13: 470160 | P13: 271515 | Q13: 232067 | R13: 108278 | S13: 88662 | T13: 2834180 | U13: -0.108
C14: Shoulder Season (Apr, May, Sept, Oct) | D14: =SUM(K25,L25,P25,Q25) -> 0.32390823 | G14: 2021 | H14: 86065 | I14: 93430 | J14: 171050 | K14: 234442 | L14: 396362 | M14: 319611 | N14: 594272 | O14: 437313 | P14: 343696 | Q14: 253640 | R14: 144881 | S14: 102448 | T14: 3177210 | U14: 0.386
C15: Peak Season (June - Aug) | D15: =SUM(M25:O25) -> 0.48345366 | G15: 2020 | H15: 82444 | I15: 87813 | J15: 93273 | K15: 91272 | L15: 154428 | M15: 341505 | N15: 427408 | O15: 389689 | P15: 225594 | Q15: 227773 | R15: 78893 | S15: 93014 | T15: 2293106 | U15: 0.074
C16: May - Oct | D16: =SUM(L25:Q25) -> 0.75352812 | G16: 2019 | H16: 69916 | I16: 85702 | J16: 219070 | K16: 107862 | L16: 142403 | M16: 302203 | N16: 449968 | O16: 290469 | P16: 206226 | Q16: 105984 | R16: 79674 | S16: 74808 | T16: 2134285 | U16: 0.215
G17: 2018 | H17: 70652 | I17: 70450 | J17: 128682 | K17: 93585 | L17: 143790 | M17: 240295 | N17: 421553 | O17: 204010 | P17: 167089 | Q17: 132862 | R17: 52878 | S17: 30233 | T17: 1756079 | U17: -0.186
G18: 2017 | H18: 60576 | I18: 85561 | J18: 90620 | K18: 102570 | L18: 149426 | M18: 247641 | N18: 319946 | O18: 462357 | P18: 405688 | Q18: 82494 | R18: 87193 | S18: 64399 | T18: 2158471 | U18: 0.271
G19: 2016 | H19: 56588 | I19: 73072 | J19: 90653 | K19: 99945 | L19: 175447 | M19: 242632 | N19: 308792 | O19: 219929 | P19: 179245 | Q19: 115180 | R19: 82775 | S19: 53965 | T19: 1698223 | U19: 0.035
G20: 2015 | H20: 55607 | I20: 47594 | J20: 93170 | K20: 93419 | L20: 141525 | M20: 174125 | N20: 362197 | O20: 262479 | P20: 169403 | Q20: 101082 | R20: 75316 | S20: 64278 | T20: 1640195 | U20: 0.056
G21: 2014 | H21: 40701 | I21: 51423 | J21: 85786 | K21: 89324 | L21: 161258 | M21: 215070 | N21: 283291 | O21: 255908 | P21: 144874 | Q21: 102336 | R21: 64236 | S21: 59165 | T21: 1553372 | U21: -0.076
G22: 2013 | H22: 54937 | I22: 47432 | J22: 77032 | K22: 101281 | L22: 144046 | M22: 219493 | N22: 357123 | O22: 304087 | P22: 190536 | Q22: 78671 | R22: 62707 | S22: 44350 | T22: 1681695 | U22: -0.11
G23: 2012 | H23: 58521 | I23: 51948 | J23: 106271 | K23: 73145 | L23: 194496 | M23: 270881 | N23: 361124 | O23: 260821 | P23: 160416 | Q23: 228117 | R23: 67680 | S23: 55961 | T23: 1889381 | U23: 0.027
G24: Average | H24: =AVERAGE(H13:H23) -> 64330.909 | I24: =AVERAGE(I13:I23) -> 69890.636 | J24: =AVERAGE(J13:J23) -> 116639.82 | K24: =AVERAGE(K13:K23) -> 111662 | L24: =AVERAGE(L13:L23) -> 185234.91 | M24: =AVERAGE(M13:M23) -> 273834.82 | N24: =AVERAGE(N13:N23) -> 405560.82 | O24: =AVERAGE(O13:O23) -> 323383.82 | ... S24: =AVERAGE(S13:S23) -> 66480.273 | T24: =SUM(H24:S24) -> 2074199.7 | U24: =AVERAGE(U13:U23) -> 0.053090909
G25: % Total | H25: =H24/$T$24 -> 0.031014809 | I25: =I24/$T$24 -> 0.03369523 | J25: =J24/$T$24 -> 0.056233648 | K25: =K24/$T$24 -> 0.053833774 | L25: =L24/$T$24 -> 0.089304278 | M25: =M24/$T$24 -> 0.1320195 | N25: =N24/$T$24 -> 0.19552641 | O25: =O24/$T$24 -> 0.15590775 | ... S25: =S24/$T$24 -> 0.032051047 | T25: =SUM(H25:S25) -> 1
G26: % July | H26: =H24/$N$24 -> 0.1586221 | I26: =I24/$N$24 -> 0.17233084 | J26: =J24/$N$24 -> 0.2876013 | K26: =K24/$N$24 -> 0.27532739 | L26: =L24/$N$24 -> 0.45673768 | M26: =M24/$N$24 -> 0.67520038 | N26: =N24/$N$24 -> 1 | O26: =O24/$N$24 -> 0.79737441 | ... S26: =S24/$N$24 -> 0.16392183
G29: George Rogers Clark NHP
C30: Seasonal Demand | H30: JAN | I30: FEB | J30: MAR | K30: APR | L30: MAY | M30: JUN | N30: JUL | O30: AUG | P30: SEP | Q30: OCT | R30: NOV | S30: DEC | T30: Annual Total | U30: YoY % Change
C31: Low Season (Nov-March) | D31: =SUM(H43,I43,J43,R43,S43) -> 0.1770633 | G31: 2022 | H31: 2101 | I31: 2439 | J31: 5189 | K31: 8533 | L31: 29727 | M31: 10862 | N31: 25280 | O31: 12347 | P31: 7360 | Q31: 11846 | R31: 4078 | S31: 3467 | T31: 123229 | U31: 0.062
C32: Shoulder Season (Apr, May, Sept, Oct) | D32: =SUM(K43,L43,P43,Q43) -> 0.4615135 | G32: 2021 | H32: 2268 | I32: 2486 | J32: 5534 | K32: 6147 | L32: 26402 | M32: 9019 | N32: 27354 | O32: 12432 | P32: 9305 | Q32: 6750 | R32: 4522 | S32: 3869 | T32: 116088 | U32: 1.069
C33: Peak Season (June - Aug) | D33: =SUM(M43:O43) -> 0.3614232 | G33: 2020 | H33: 2407 | I33: 3139 | J33: 2471 | K33: 3800 | L33: 4100 | M33: 6819 | N33: 6914 | O33: 6549 | P33: 6491 | Q33: 7098 | R33: 4297 | S33: 2023 | T33: 56108 | U33: -0.6
C34: May - Oct | D34: =SUM(L43:Q43) -> 0.7653696 | G34: 2019 | H34: 633 | I34: 2404 | J34: 4104 | K34: 11845 | L34: 36257 | M34: 8702 | N34: 28453 | O34: 15558 | P34: 10039 | Q34: 9856 | R34: 5608 | S34: 6671 | T34: 140130 | U34: 0.156
G35: 2018 | H35: 1844 | I35: 2504 | J35: 4877 | K35: 5832 | L35: 36995 | M35: 7603 | N35: 19710 | O35: 10544 | P35: 12826 | Q35: 4923 | R35: 10144 | S35: 3385 | T35: 121187 | U35: 0.033
G36: 2017 | H36: 2029 | I36: 2771 | J36: 4633 | K36: 6406 | L36: 36198 | M36: 7028 | N36: 22815 | O36: 12948 | P36: 6911 | Q36: 5480 | R36: 6442 | S36: 3607 | T36: 117268 | U36: -0.07
G37: 2016 | H37: 2204 | I37: 2967 | J37: 4805 | K37: 7534 | L37: 37742 | M37: 7440 | N37: 28558 | O37: 10923 | P37: 7678 | Q37: 6783 | R37: 3612 | S37: 5849 | T37: 126095 | U37: -0.072
G38: 2015 | H38: 2162 | I38: 2195 | J38: 4246 | K38: 5920 | L38: 37813 | M38: 7114 | N38: 40128 | O38: 13059 | P38: 8046 | Q38: 5824 | R38: 2916 | S38: 6433 | T38: 135856 | U38: 0.085
G39: 2014 | H39: 1764 | I39: 2608 | J39: 4269 | K39: 6683 | L39: 42414 | M39: 11087 | N39: 23196 | O39: 11079 | P39: 9450 | Q39: 5688 | R39: 2954 | S39: 4026 | T39: 125218 | U39: -0.026
G40: 2013 | H40: 2398 | I40: 2808 | J40: 4640 | K40: 6989 | L40: 41436 | M40: 6803 | N40: 23704 | O40: 6257 | P40: 9639 | Q40: 3148 | R40: 13360 | S40: 7349 | T40: 128531 | U40: 0.02
G41: 2012 | H41: 2243 | I41: 2863 | J41: 4493 | K41: 6051 | L41: 32387 | M41: 9683 | N41: 18486 | O41: 7064 | P41: 7640 | Q41: 7213 | R41: 25399 | S41: 2450 | T41: 125972 | U41: -0.135
G42: Average | H42: =AVERAGE(H31:H41) -> 2004.8182 | I42: =AVERAGE(I31:I41) -> 2653.0909 | J42: =AVERAGE(J31:J41) -> 4478.2727 | K42: =AVERAGE(K31:K41) -> 6885.4545 | L42: =AVERAGE(L31:L41) -> 32861 | M42: =AVERAGE(M31:M41) -> 8378.1818 | N42: =AVERAGE(N31:N41) -> 24054.364 | O42: =AVERAGE(O31:O41) -> 10796.364 | ... S42: =AVERAGE(S31:S41) -> 4466.2727 | T42: =SUM(H42:S42) -> 119607.45 | U42: =AVERAGE(U31:U41) -> 0.047454545
G43: % Total | H43: =H42/$T$42 -> 0.016761649 | I43: =I42/$T$42 -> 0.022181652 | J43: =J42/$T$42 -> 0.037441418 | K43: =K42/$T$42 -> 0.057567102 | L43: =L42/$T$42 -> 0.2747404 | M43: =M42/$T$42 -> 0.070047321 | N43: =N42/$T$42 -> 0.20111091 | O43: =O42/$T$42 -> 0.090264973 | ... T43: =T42/$T$42 -> 1
G44: % July | H44: =H42/$N$42 -> 0.083345301 | I44: =I42/$N$42 -> 0.11029562 | J44: =J42/$N$42 -> 0.18617299 | K44: =K42/$N$42 -> 0.28624555 | L44: =L42/$N$42 -> 1.3661139 | M44: =M42/$N$42 -> 0.34830195 | N44: =N42/$N$42 -> 1 | O44: =O42/$N$42 -> 0.44883181 | ... S44: =S42/$N$42 -> 0.18567412 | T44: 1
G47: Lincoln Boyhood NMEM
...

Sheet Sheet1

Sheet SUPPLY & COMPS
A1: SUPPLY & COMPETITION ANALYSIS (REFERENCE & TRAINING) | D1: ↓ ADDITIONAL INSTRUCTIONS / STEPS / INFO BELOW ↓ | E1: YOUR PROJECT NOTES (For Sections on Left):
A2: Glamping Unit or RV Site Analysis (Database Excel Pivot Tables and Write Ups)
B3: Sage Database Search: Training Video Link (Date Video Last Updated 0/0/0):
B4: Excel Pivot Tables: Training Video Link (Date Video Last Updated 7/11/23):
C5: https://www.dropbox.com/scl/fi/jzncpyhi34ryci25nj897/Database-Training-Pivot-Tables?rlkey=pvaid9z7esq8b4fshf4hz0vcw&st=g74he5jc&dl=0
A7: Emerging Competitors
B8: EMERG. COMP. Call & Info Notes Template / Questions Example (@ End of this Column)
B9: Example Chat GPT Search and Summary Prompt (Copy & Paste):
C10: Perform an exhaustive search for and then list any campgrounds, rv parks, rv resorts, landscape hotels, landscape resorts, or glamping resorts which are new, under contruction, expanding, or in the approval or permitting process in [PROJECT STATE(S), REGION, OR COUNTY & STATE] during the past 2 years. Please cite where any information was located.
A12: Area Competitors
B13: Selecting Area Competitors: Training Video Link (Date Video Last Updated 0/0/0):
B14: Example Chat GPT Search and Summary Prompt (Copy & Paste):
C15: Perform an exhaustive search for and then create numbered and bulletized lists of each by the following types of any campgrounds, RV parks, RV resorts, landscape hotels, landscape resorts, or glamping resorts which are within [TYPE DRIVE TIME] of [TYPE PROJECT STATE(S), REGION, OR COUNTY & STATE]. Please include any data available about each business's number of lodging units or RV sites, types of units, price ranges, and a brief description of the resort. In the bullets for each property please separate the number of RV sites, lodging, units, or glamping units by their type, such as by cabins, domes, RV sites, casitas, safari tents, etc. along with any other availale information for that unit type or site. Please cite where any information was located.
A17: COMPARABLES
B18: Selecting Best Comparables: Training Video Link (Date Video Last Updated 0/0/0):
B20: BEST COMP TABLES / Write-ups / Info
B21: (*This is a start point Only: verify, FACT CHECK IT, edit, add, remove, research further, etc.)
B22: RV Sites & amenities AI prompt
C23: Create a sentence and list (separating by commas) for [TYPE RESORT NAME, ADDRESS, CITY, STATE] the total number of RV sites, number of back-in and pull-thru RV sites, RV hook-ups available (20/30/50 amp electricity, water, sewer), RV site surface paved/gravel/etc., and list RV site amenities (picnic table/seating, fire pit, etc.), Wi-Fi, and average RV site dimensions (such as 40' x 70').
B25: Units & unit amenities AI prompt
C26: Create a sentence and list (separating by commas) for [TYPE RESORT NAME, ADDRESS, CITY, STATE] the total number of lodging units, type of units with number of rooms/bedrooms and quanitity of each unit type, in-unit amenities (private bathroom or shared bathhouse, full kitchen or kitchenette, bed sizes/types, loft), parking at unit or walking distance, and list at-unit amenities (picnic table/seating, fire pit, etc.), Wi-Fi, TV, and any available average information on size, number of guests the unit sleeps, and/or number of bedrooms for that unit type (such as sleeps 4 guests, 400 SF, or 2 bedroom).
B28: Property AI prompt
C29: Create a sentence and list (separating by commas) for [TYPE RESORT NAME, ADDRESS, CITY, STATE] the property characteristics to include number of acres, terrain (flat vs. hilly), mature trees or not, wooded or field, any ponds/lake/creek/river, walking trails, modern or classic style, paved/gravel/dirt roads, walkway surface type, quality overall and how well maintained if known, new or old build, etc.
B31: Resort amenities AI prompt
C32: Create a sentence and list (separating by commas) for [TYPE RESORT NAME, ADDRESS, CITY, STATE] the property/resort amenities that are for communal use. For example: 10,600-square-foot clubhouse with spa and fitness amenities, covered porte-cochère, wash stations, shared restrooms and shower facilities, picnic pavilions, an off-leash dog park, playgrounds, fire pits, a one-mile interpretive trail, pickleball courts, and landscaped recreation areas.
B34: Location AI prompt
C35: Write a very brief paragraph / sentence(s) listing with commas, for [TYPE RESORT NAME, ADDRESS, CITY, STATE] about its location as it relates to the setting (remote, rural, urban), road access, and driving times in minutes to the nearest city/town/census-designated place, nearest large city, nearest international airport, nearest full grocery store, nearest gas station, restaurants, bars, coffee shops, unique shopping, and important attractions of any sort that would draw guests to this type of resort (especially outdoor focused attractions, such as lakes, national or state parks, a ski area, etc.).
B37: Brand strength AI prompt
C38: Write a very brief paragraph / sentence(s) listing with commas, for [TYPE RESORT NAME, ADDRESS, CITY, STATE] the information that helps represent the business's brand strength, including ratings as applicable for Good Sam: (the 3 rated areas out of 10 each i.e., 10/10/10), Tripadvisor ratings (number score/stars out of 5, and total number of reviews/ratings, i.e. 4.5 of 342 reviews), Google ratings/reviews: (number score/stars out of 5, and total number of reviews/ratings, , i.e. 4.5 of 342 reviews), quality of website/photography/videos/booking platform, any major affiliated/parent company brand, awards won, and whether they are new or established, etc.
B40: Occupancy (look at their booking platform and call the resort to interview staff)
A43: Overview
B44: *Select photos / maps / diagrams for each "best comp" similar to Word template examples
A46: Best Comparables Information / Descriptions (Table In "Best Comps" Excel Sheet)
B47: Comparables Descriptions How-To: Training Video Link (Date Video Last Updated 0/0/0):
B48: *Guidance/How-To/?'s is in the "Best Comps" Excel Sheet next to the table sections
B49: Best Comps Occupancy Info & % Reference Sheet Based on Call Convo
B50: Call & Info Link to Sample How-To Sheet Link
B52: *Make Notes: Template for Occupancy Calls to Properties in "Best Comps" Excel Sheet/Tab
A54: Subject Quality Score Excel Table (Table In "Best Comps" Excel Sheet)
B55: Subject Quality Score How-To: Training Video Link (Date Video Last Updated 0/0/0):
...

Sheet Unit Type #1 Data
A1: Avg. Rate (Next 12 Months) | B1: (Multiple Items)
A2: Avg. Retail Daily Rate 2024 | B2: (Multiple Items)
A3: Toilet | B3: Yes
A4: Shower | B4: Yes
A5: Cooking equipment | B5: Yes
A6: Occupancy rate 2024 | B6: (Multiple Items)
A8: Location | B8: Average Retail Daily Rate 2024 | C8: Average Rate (Next 12 Months) | D8: Average of Low Rate (Next 12 Months) | E8: Average of High Rate (Next 12 Months) | F8: Average of Occupancy rate 2024
A9: Minnesota | B9: 210.27778 | C9: 229.16667 | D9: 218.66667 | E9: 240.88889 | F9: 0.63222222
A10: Braham | B10: 100 | C10: 100 | D10: 100 | E10: 100 | F10: 0.13
A11: Deerwood | B11: 323 | C11: 358 | D11: 336 | E11: 378 | F11: 0.28
A12: Duluth | B12: 132 | C12: 110 | D12: 100 | E12: 130 | F12: 0.21
A13: Fergus Falls | B13: 266 | C13: 295.8 | D13: 277 | E13: 313.4 | F13: 0.926
A14: Hinckley | B14: 268 | C14: 295 | D14: 292.5 | E14: 297.5 | F14: 0.5825
A15: Ogema | B15: 195 | C15: 215 | D15: 194 | E15: 244 | F15: 0.59
A16: Outing | B16: 118 | C16: 152 | D16: 152 | E16: 152 | F16: 0.93
A17: Pine City | B17: 113.66667 | C17: 114 | D17: 105 | E17: 127 | F17: 0.63333333
A18: Winona | B18: 174 | C18: 189 | D18: 184 | E18: 194 | F18: 0.38
A19: Wisconsin | B19: 222.5 | C19: 228.25 | D19: 224.41667 | E19: 231.83333 | F19: 0.59166667
A20: Black River Falls | B20: 311 | C20: 337 | D20: 304 | E20: 367 | F20: 0.69
... A31: Grand Total | B31: 215.16667 | C31: 228.8 | D31: 220.96667 | E31: 237.26667 | F31: 0.616

Sheet Unit Type #2 Data
A1: Avg. Retail Daily Rate 2024 | B1: (Multiple Items)
A2: Occupancy rate 2024 | B2: (Multiple Items)
A3: Toilet | B3: Yes
A4: Shower | B4: (Multiple Items)
A5: Cooking equipment | B5: (Multiple Items)
A7: Location | B7: Average Retail Daily Rate 2024 | C7: Average Rate (Next 12 Months) | D7: Average of Low Rate (Next 12 Months) | E7: Average of High Rate (Next 12 Months) | F7: Average of Occupancy rate 2024
A8: Alabama | B8: 181 | C8: 103 | D8: 92 | E8: 131 | F8: 0.95
A9: Arizona | B9: 135.66667 | C9: 138.33333 | D9: 133 | E9: 143.66667 | F9: 0.51333333
A10: California | B10: 269.15789 | C10: 296.73684 | D10: 277.73684 | E10: 314.94737 | F10: 0.57263158
A11: Colorado | B11: 119 | C11: 119 | D11: 119 | E11: 120 | F11: 0.8
A12: Georgia | B12: 379 | C12: 379 | D12: 379 | E12: 379 | F12: 0.89
A13: Hawaii | B13: 248.5 | C13: 215.5 | D13: 214.5 | E13: 217 | F13: 0.515
A14: Iowa | B14: 101 | C14: 107 | D14: 101 | E14: 113 | F14: 0.54
A15: Maine | B15: 120 | C15: 195 | D15: 162 | E15: 236 | F15: 0.875
A16: Michigan | B16: 145 | C16: 141 | D16: 136 | E16: 145 | F16: 0.77
A17: New Hampshire | B17: 171 | C17: 178 | D17: 167 | E17: 188 | F17: 0.68
A18: New Mexico | B18: 214.4 | C18: 223.8 | D18: 214.2 | E18: 233 | F18: 0.578
A19: New York | B19: 292.5 | C19: 317 | D19: 293.5 | E19: 338 | F19: 0.195
... A26: Grand Total | B26: 232.18182 | C26: 242.28788 | D26: 227.43939 | E26: 257.10606 | F26: 0.56833333

Sheet Unit Type #3 Data
A1: Avg. Retail Daily Rate 2024 | B1: (Multiple Items)
A2: Occupancy rate 2024 | B2: (Multiple Items)
A3: Toilet | B3: Yes
A4: Shower | B4: (Multiple Items)
A5: Cooking equipment | B5: (Multiple Items)
A7: Location | B7: Average Retail Daily Rate 2024 | C7: Average Rate (Next 12 Months) | D7: Average of Low Rate (Next 12 Months) | E7: Average of High Rate (Next 12 Months) | F7: Average of Occupancy rate 2024
A8: Alabama | B8: 151 | C8: 149 | D8: 144.5 | E8: 153 | F8: 0.25
A9: Arkansas | B9: 145 | C9: 152 | D9: 147 | E9: 156 | F9: 0.51
A10: California | B10: 162 | C10: 188.66667 | D10: 178.66667 | E10: 198 | F10: 0.58666667
A11: Florida | B11: 215 | C11: 210 | D11: 210 | E11: 210 | F11: 0.99
A12: Georgia | B12: 234.5 | C12: 262 | D12: 251.5 | E12: 271.75 | F12: 0.495
A13: Hawaii | B13: 207.5 | C13: 207.5 | D13: 207.5 | E13: 207.5 | F13: 0.855
A14: Idaho | B14: 202.66667 | C14: 260 | D14: 248.33333 | E14: 270.33333 | F14: 0.69
A15: Indiana | B15: 198 | C15: 213 | D15: 196 | E15: 228 | F15: 0.67
A16: Kentucky | B16: 262.33333 | C16: 265.33333 | D16: 260.33333 | E16: 269.66667 | F16: 0.52666667
A17: Maine | B17: 137 | C17: 130 | D17: 130 | E17: 130 | F17: 0.71
A18: Michigan | B18: 106 | C18: 119 | D18: 114 | E18: 124 | F18: 0.23
A19: New Mexico | B19: 185.66667 | C19: 219.33333 | D19: 203.66667 | E19: 235.66667 | F19: 0.61666667
... A29: Grand Total | B29: 235.11538 | C29: 250.57692 | D29: 239.07692 | E29: 263.26923 | F29: 0.6

Sheet Unit Type #4 Data

Sheet Best Comps
B1: → OCCUPANCY CALL QUESTION EXAMPLES / INFO TO GATHER - FAR RIGHT → | R1: ↓ OCCUPANCY CALL QUESTION EXAMPLES / INFO TO COLLECT - BELOW ↓
F2: INTERNAL - SUBJECT PROPERTY NOTES (Add Property Name): | R2: CALL QUESTION EXAMPLES / INFO TO COLLECT:
B3: Subject | C3: 4.25 | D3: Description | R3: (YOUR NOTES: about reaching them or voicemails, emails, or texts sent and when) • BUSIEST TIMES & HOW FULL: When are the busiest times of year? How full are weekends each season vs. How full are weekdays each season? (totally full, half full, mostly empty) • SLOWEST TIMES & HOW FULL: Quietest times? Weekend vs. Weekday how full when slow? • CLOSED WHEN: Do you close for periods? If so, when are you closed? • BOOK HOW FAR OUT: When busy, how far in advance should I book to get a spot? • AREA ATTRACTIONS: What are the biggest draws for people to the area? • ON-SITE AMENITIES: Double check for all on-site amenities (per unit and communal use)? • RATES – HIGHEST & LOWEST: - What are the busy time rates or highest rates (if not already obtained)? - Slow time rates or lowest rates (if not already obtained)?
B4: Unit Type(s) | D4: 17 small treehouses, 4 large treehouses, 10 small domes, 4 large domes, 15 mirrored cabins, and 1 luxury signature unit.
B5: Unit Amenities | D5: Very high quality furnishings with full bath, bedroom, living area, hot tubs at large treehouses, large dome, signature treehouse, and mirrored cabins. Each unit will have outdoor seating and deck with grill and fire pit.
B6: Property | D6: Forested 500 acres, very high quality, brand new, dirt roads with gravel walkways, and has a small pond on site.
B7: Property Amenities | D7: Limited F&B in lodge which includes a fitness center, meeting area, and business center. Communal hot tub, sauna, and pool.
B8: Location | D8: 70 minutes north of Kansas City, adjacent to a waterfront marina, and located on Nickajack Lake with access to the lake via the adjacent marina. Near restaurants, gas station, and grocery store.
B9: Brand Strength | D9: Assumed to be strong in Year 5 with high quality and professional photos, videos, website, and booking platform, plus good social media and reviews.
F11: INTERNAL - OCCUPANCY CALL NOTES (Add Property Name): | R11: CALL QUESTION EXAMPLES / INFO TO COLLECT:
B12: Bolt Farm Treehouses | C12: 3.75 | D12: Description | R12: (YOUR NOTES: about reaching them or voicemails, emails, or texts sent and when) • • BUSIEST TIMES & HOW FULL: When are the busiest times of year? How full are weekends each season vs. How full are weekdays each season? (totally full, half full, mostly empty) • SLOWEST TIMES & HOW FULL: Quietest times? Weekend vs. Weekday how full when slow? • CLOSED WHEN: Do you close for periods? If so, when are you closed? • BOOK HOW FAR OUT: When busy, how far in advance should I book to get a spot? • AREA ATTRACTIONS: What are the biggest draws for people to the area? • ON-SITE AMENITIES: Double check for all on-site amenities (per unit and communal use)? • RATES – HIGHEST & LOWEST: - What are the busy time rates or highest rates (if not already obtained)? - Slow time rates or lowest rates (if not already obtained)?
B13: Unit Type(s) | D13: Lodge rooms/suites, cabins, Conestoga wagons, and tipis.
B14: Unit Amenities | D14: Wagons and tipis have detached private bathroom, ac, Wi-Fi, coffee maker; cabins have en suite bathroom, kitchen, seating area, grill, deck; lodge rooms have microwave, mini fridge, and patio seating.
B15: Property | D15: 58 acre resort, has a small pond with fishing, treed property, parking is a 2 minute walk from the units, and has dirt roads leading to the property.
B16: Property Amenities | D16: Clubhouse with bar, restaurant, spa, swimming pool, communal fire pit, lawn games, fitness center with sauna, mini-golf, pedal boats, canoes and kayaks, lazy river, paved trails, and playground.
